{
    "registryname": "advanced_water_pump",
    "localizedname": "Advanced Water Pump",
    "modifiers": [],
    "parts": [
        {
            "x": 3,
            "y": -2,
            "z": 3,
            "elements": "immersiveengineering:metal_decoration1@1"
        },
        {
            "x": 2,
            "y": -2,
            "z": 3,
            "elements": "immersiveengineering:metal_decoration1@1"
        },
        {
            "x": 1,
            "y": -2,
            "z": 3,
            "elements": "immersiveengineering:metal_decoration1@1"
        },
        {
            "x": 0,
            "y": -2,
            "z": 3,
            "elements": "immersiveengineering:metal_decoration1@1"
        },
        {
            "x": -1,
            "y": -2,
            "z": 3,
            "elements": "immersiveengineering:metal_decoration1@1"
        },
        {
            "x": -2,
            "y": -2,
            "z": 3,
            "elements": "immersiveengineering:metal_decoration1@1"
        },
        {
            "x": -3,
            "y": -2,
            "z": 3,
            "elements": "immersiveengineering:metal_decoration1@1"
        },
        {
            "x": -4,
            "y": -2,
            "z": 3,
            "elements": "immersiveengineering:metal_decoration1@1"
        },
        {
            "x": -5,
            "y": -2,
            "z": 3,
            "elements": "immersiveengineering:metal_decoration1@1"
        },
        {
            "x": -6,
            "y": -2,
            "z": 3,
            "elements": "immersiveengineering:metal_decoration1@1"
        },
        {
            "x": -7,
            "y": -2,
            "z": 3,
            "elements": "immersiveengineering:metal_decoration1@1"
        },
        {
            "x": -8,
            "y": -2,
            "z": 3,
            "elements": "immersiveengineering:metal_decoration1@1"
        },
        {
            "x": -9,
            "y": -2,
            "z": 3,
            "elements": "immersiveengineering:metal_decoration1@1"
        },
        {
            "x": 3,
            "y": -2,
            "z": 2,
            "elements": "immersiveengineering:metal_decoration1@1"
        },
        {
            "x": 2,
            "y": -2,
            "z": 2,
            "elements": "immersiveengineering:metal_decoration1@1"
        },
        {
            "x": 1,
            "y": -2,
            "z": 2,
            "elements": "immersiveengineering:metal_decoration1@1"
        },
        {
            "x": 0,
            "y": -2,
            "z": 2,
            "elements": "immersiveengineering:metal_decoration1@1"
        },
        {
            "x": -1,
            "y": -2,
            "z": 2,
            "elements": "immersiveengineering:metal_decoration1@1"
        },
        {
            "x": -2,
            "y": -2,
            "z": 2,
            "elements": "immersiveengineering:metal_decoration1@1"
        },
        {
            "x": -3,
            "y": -2,
            "z": 2,
            "elements": "immersiveengineering:metal_decoration1@1"
        },
        {
            "x": -6,
            "y": -2,
            "z": 2,
            "elements": "modularmachinery:blockcasing@0"
        },
        {
            "x": -7,
            "y": -2,
            "z": 2,
            "elements": "modularmachinery:blockcasing@0"
        },
        {
            "x": -8,
            "y": -2,
            "z": 2,
            "elements": "modularmachinery:blockcasing@0"
        },
        {
            "x": -9,
            "y": -2,
            "z": 2,
            "elements": "immersiveengineering:metal_decoration1@1"
        },
        {
            "x": 3,
            "y": -2,
            "z": 1,
            "elements": "immersiveengineering:metal_decoration1@1"
        },
        {
            "x": 2,
            "y": -2,
            "z": 1,
            "elements": "immersiveengineering:metal_decoration1@1"
        },
        {
            "x": 1,
            "y": -2,
            "z": 1,
            "elements": "immersiveengineering:metal_decoration1@1"
        },
        {
            "x": 0,
            "y": -2,
            "z": 1,
            "elements": "immersiveengineering:metal_decoration1@1"
        },
        {
            "x": -1,
            "y": -2,
            "z": 1,
            "elements": "immersiveengineering:metal_decoration1@1"
        },
        {
            "x": -2,
            "y": -2,
            "z": 1,
            "elements": "immersiveengineering:metal_decoration1@1"
        },
        {
            "x": -3,
            "y": -2,
            "z": 1,
            "elements": "immersiveengineering:metal_decoration1@1"
        },
        {
            "x": -4,
            "y": -2,
            "z": 1,
            "elements": "immersiveengineering:metal_decoration1@1"
        },
        {
            "x": -5,
            "y": -2,
            "z": 1,
            "elements": "immersiveengineering:metal_decoration1@1"
        },
        {
            "x": -6,
            "y": -2,
            "z": 1,
            "elements": "modularmachinery:blockcasing@0"
        },
        {
            "x": -7,
            "y": -2,
            "z": 1,
            "elements": "modularmachinery:blockcasing@0"
        },
        {
            "x": -8,
            "y": -2,
            "z": 1,
            "elements": "modularmachinery:blockcasing@0"
        },
        {
            "x": -9,
            "y": -2,
            "z": 1,
            "elements": "immersiveengineering:metal_decoration1@1"
        },
        {
            "x": 3,
            "y": -2,
            "z": 0,
            "elements": "immersiveengineering:metal_decoration1@1"
        },
        {
            "x": 2,
            "y": -2,
            "z": 0,
            "elements": "immersiveengineering:metal_decoration1@1"
        },
        {
            "x": 1,
            "y": -2,
            "z": 0,
            "elements": "immersiveengineering:metal_decoration1@1"
        },
        {
            "x": 0,
            "y": -2,
            "z": 0,
            "elements": "immersiveengineering:metal_decoration1@1"
        },
        {
            "x": -1,
            "y": -2,
            "z": 0,
            "elements": "immersiveengineering:metal_decoration1@1"
        },
        {
            "x": -2,
            "y": -2,
            "z": 0,
            "elements": "immersiveengineering:metal_decoration1@1"
        },
        {
            "x": -3,
            "y": -2,
            "z": 0,
            "elements": "immersiveengineering:metal_decoration1@1"
        },
        {
            "x": -4,
            "y": -2,
            "z": 0,
            "elements": "immersiveengineering:metal_decoration1@1"
        },
        {
            "x": -5,
            "y": -2,
            "z": 0,
            "elements": "immersiveengineering:metal_decoration1@1"
        },
        {
            "x": -6,
            "y": -2,
            "z": 0,
            "elements": "modularmachinery:blockcasing@0"
        },
        {
            "x": -7,
            "y": -2,
            "z": 0,
            "elements": "modularmachinery:blockcasing@0"
        },
        {
            "x": -8,
            "y": -2,
            "z": 0,
            "elements": "modularmachinery:blockcasing@0"
        },
        {
            "x": -9,
            "y": -2,
            "z": 0,
            "elements": "immersiveengineering:metal_decoration1@1"
        },
        {
            "x": 3,
            "y": -2,
            "z": -1,
            "elements": "immersiveengineering:metal_decoration1@1"
        },
        {
            "x": 2,
            "y": -2,
            "z": -1,
            "elements": "immersiveengineering:metal_decoration1@1"
        },
        {
            "x": 1,
            "y": -2,
            "z": -1,
            "elements": "immersiveengineering:metal_decoration1@1"
        },
        {
            "x": 0,
            "y": -2,
            "z": -1,
            "elements": "immersiveengineering:metal_decoration1@1"
        },
        {
            "x": -1,
            "y": -2,
            "z": -1,
            "elements": "immersiveengineering:metal_decoration1@1"
        },
        {
            "x": -2,
            "y": -2,
            "z": -1,
            "elements": "immersiveengineering:metal_decoration1@1"
        },
        {
            "x": -3,
            "y": -2,
            "z": -1,
            "elements": "immersiveengineering:metal_decoration1@1"
        },
        {
            "x": -4,
            "y": -2,
            "z": -1,
            "elements": "immersiveengineering:metal_decoration1@1"
        },
        {
            "x": -5,
            "y": -2,
            "z": -1,
            "elements": "immersiveengineering:metal_decoration1@1"
        },
        {
            "x": -6,
            "y": -2,
            "z": -1,
            "elements": "immersiveengineering:metal_decoration1@1"
        },
        {
            "x": -7,
            "y": -2,
            "z": -1,
            "elements": "immersiveengineering:metal_decoration1@1"
        },
        {
            "x": -8,
            "y": -2,
            "z": -1,
            "elements": "immersiveengineering:metal_decoration1@1"
        },
        {
            "x": -9,
            "y": -2,
            "z": -1,
            "elements": "immersiveengineering:metal_decoration1@1"
        },
        {
            "x": -7,
            "y": -2,
            "z": -2,
            "elements": "immersiveengineering:sheetmetal@8"
        },
        {
            "x": 3,
            "y": -1,
            "z": 3,
            "elements": "immersiveengineering:metal_decoration1@1"
        },
        {
            "x": -3,
            "y": -1,
            "z": 3,
            "elements": "immersiveengineering:metal_decoration1@1"
        },
        {
            "x": -6,
            "y": -1,
            "z": 3,
            "elements": "modularmachinery:blockcasing@0"
        },
        {
            "x": -7,
            "y": -1,
            "z": 3,
            "elements": "modularmachinery:blockcasing@0"
        },
        {
            "x": -8,
            "y": -1,
            "z": 3,
            "elements": "modularmachinery:blockcasing@0"
        },
        {
            "x": -9,
            "y": -1,
            "z": 3,
            "elements": "immersiveengineering:metal_decoration1@1"
        },
        {
            "x": 2,
            "y": -1,
            "z": 2,
            "elements": "modularmachinery:blockcasing@0"
        },
        {
            "x": 1,
            "y": -1,
            "z": 2,
            "elements": "libvulpes:coil0@4"
        },
        {
            "x": 0,
            "y": -1,
            "z": 2,
            "elements": "modularmachinery:blockcasing@0"
        },
        {
            "x": -1,
            "y": -1,
            "z": 2,
            "elements": "libvulpes:coil0@4"
        },
        {
            "x": -2,
            "y": -1,
            "z": 2,
            "elements": "modularmachinery:blockcasing@0"
        },
        {
            "x": -6,
            "y": -1,
            "z": 2,
            "elements": "modularmachinery:blockcasing@0"
        },
        {
            "x": -8,
            "y": -1,
            "z": 2,
            "elements": "modularmachinery:blockcasing@0"
        },
        {
            "x": 2,
            "y": -1,
            "z": 1,
            "elements": "modularmachinery:blockcasing@0"
        },
        {
            "x": 1,
            "y": -1,
            "z": 1,
            "elements": "libvulpes:coil0@4"
        },
        {
            "x": 0,
            "y": -1,
            "z": 1,
            "elements": "modularmachinery:blockcasing@0"
        },
        {
            "x": -1,
            "y": -1,
            "z": 1,
            "elements": "libvulpes:coil0@4"
        },
        {
            "x": -2,
            "y": -1,
            "z": 1,
            "elements": "modularmachinery:blockcasing@0"
        },
        {
            "x": -6,
            "y": -1,
            "z": 1,
            "elements": "modularmachinery:blockcasing@0"
        },
        {
            "x": -7,
            "y": -1,
            "z": 1,
            "elements": "nuclearcraft:turbine_rotor_blade_steel"
        },
        {
            "x": -8,
            "y": -1,
            "z": 1,
            "elements": "modularmachinery:blockcasing@0"
        },
        {
            "x": 2,
            "y": -1,
            "z": 0,
            "elements": "modularmachinery:blockcasing@0"
        },
        {
            "x": 1,
            "y": -1,
            "z": 0,
            "elements": "libvulpes:coil0@4"
        },
        {
            "x": 0,
            "y": -1,
            "z": 0,
            "elements": "modularmachinery:blockcasing@0"
        },
        {
            "x": -1,
            "y": -1,
            "z": 0,
            "elements": "libvulpes:coil0@4"
        },
        {
            "x": -2,
            "y": -1,
            "z": 0,
            "elements": "modularmachinery:blockcasing@0"
        },
        {
            "x": -6,
            "y": -1,
            "z": 0,
            "elements": "modularmachinery:blockcasing@0"
        },
        {
            "x": -8,
            "y": -1,
            "z": 0,
            "elements": "modularmachinery:blockcasing@0"
        },
        {
            "x": 3,
            "y": -1,
            "z": -1,
            "elements": "immersiveengineering:metal_decoration1@1"
        },
        {
            "x": -3,
            "y": -1,
            "z": -1,
            "elements": "immersiveengineering:metal_decoration1@1"
        },
        {
            "x": -6,
            "y": -1,
            "z": -1,
            "elements": "modularmachinery:blockcasing@0"
        },
        {
            "x": -7,
            "y": -1,
            "z": -1,
            "elements": "modularmachinery:blockcasing@0"
        },
        {
            "x": -8,
            "y": -1,
            "z": -1,
            "elements": "modularmachinery:blockcasing@0"
        },
        {
            "x": -9,
            "y": -1,
            "z": -1,
            "elements": "immersiveengineering:metal_decoration1@1"
        },
        {
            "x": -7,
            "y": -1,
            "z": -2,
            "elements": "immersiveengineering:sheetmetal@8"
        },
        {
            "x": 3,
            "y": 0,
            "z": 3,
            "elements": "immersiveengineering:metal_decoration1@1"
        },
        {
            "x": -3,
            "y": 0,
            "z": 3,
            "elements": "immersiveengineering:metal_decoration1@1"
        },
        {
            "x": -4,
            "y": 0,
            "z": 3,
            "elements": "immersiveengineering:metal_decoration1@1"
        },
        {
            "x": -5,
            "y": 0,
            "z": 3,
            "elements": "immersiveengineering:metal_decoration1@1"
        },
        {
            "x": -6,
            "y": 0,
            "z": 3,
            "elements": "modularmachinery:blockcasing@0"
        },
        {
            "x": -7,
            "y": 0,
            "z": 3,
            "elements": "modularmachinery:blockcasing@0"
        },
        {
            "x": -8,
            "y": 0,
            "z": 3,
            "elements": "modularmachinery:blockcasing@0"
        },
        {
            "x": -9,
            "y": 0,
            "z": 3,
            "elements": "immersiveengineering:metal_decoration1@1"
        },
        {
            "x": 2,
            "y": 0,
            "z": 2,
            "elements": "modularmachinery:blockcasing@0"
        },
        {
            "x": 1,
            "y": 0,
            "z": 2,
            "elements": "libvulpes:coil0@4"
        },
        {
            "x": 0,
            "y": 0,
            "z": 2,
            "elements": "modularmachinery:blockenergyinputhatch"
        },
        {
            "x": -1,
            "y": 0,
            "z": 2,
            "elements": "libvulpes:coil0@4"
        },
        {
            "x": -2,
            "y": 0,
            "z": 2,
            "elements": "modularmachinery:blockcasing@0"
        },
        {
            "x": -6,
            "y": 0,
            "z": 2,
            "elements": "modularmachinery:blockcasing@0"
        },
        {
            "x": -7,
            "y": 0,
            "z": 2,
            "elements": "nuclearcraft:turbine_rotor_blade_steel"
        },
        {
            "x": -8,
            "y": 0,
            "z": 2,
            "elements": "modularmachinery:blockcasing@0"
        },
        {
            "x": 2,
            "y": 0,
            "z": 1,
            "elements": "nuclearcraft:turbine_rotor_bearing"
        },
        {
            "x": 1,
            "y": 0,
            "z": 1,
            "elements": "nuclearcraft:turbine_rotor_shaft"
        },
        {
            "x": 0,
            "y": 0,
            "z": 1,
            "elements": "nuclearcraft:turbine_rotor_shaft"
        },
        {
            "x": -1,
            "y": 0,
            "z": 1,
            "elements": "nuclearcraft:turbine_rotor_shaft"
        },
        {
            "x": -2,
            "y": 0,
            "z": 1,
            "elements": "nuclearcraft:turbine_rotor_shaft"
        },
        {
            "x": -3,
            "y": 0,
            "z": 1,
            "elements": "nuclearcraft:turbine_rotor_shaft"
        },
        {
            "x": -4,
            "y": 0,
            "z": 1,
            "elements": "nuclearcraft:turbine_rotor_shaft"
        },
        {
            "x": -5,
            "y": 0,
            "z": 1,
            "elements": "nuclearcraft:turbine_rotor_shaft"
        },
        {
            "x": -6,
            "y": 0,
            "z": 1,
            "elements": "nuclearcraft:turbine_rotor_shaft"
        },
        {
            "x": -7,
            "y": 0,
            "z": 1,
            "elements": "nuclearcraft:turbine_rotor_shaft"
        },
        {
            "x": -8,
            "y": 0,
            "z": 1,
            "elements": "modularmachinery:blockcasing@0"
        },
        {
            "x": 2,
            "y": 0,
            "z": 0,
            "elements": "modularmachinery:blockcasing@0"
        },
        {
            "x": 1,
            "y": 0,
            "z": 0,
            "elements": "libvulpes:coil0@4"
        },
        {
            "x": -1,
            "y": 0,
            "z": 0,
            "elements": "libvulpes:coil0@4"
        },
        {
            "x": -2,
            "y": 0,
            "z": 0,
            "elements": "modularmachinery:blockcasing@0"
        },
        {
            "x": -6,
            "y": 0,
            "z": 0,
            "elements": "modularmachinery:blockcasing@0"
        },
        {
            "x": -7,
            "y": 0,
            "z": 0,
            "elements": "nuclearcraft:turbine_rotor_blade_steel"
        },
        {
            "x": -8,
            "y": 0,
            "z": 0,
            "elements": "modularmachinery:blockcasing@0"
        },
        {
            "x": 3,
            "y": 0,
            "z": -1,
            "elements": "immersiveengineering:metal_decoration1@1"
        },
        {
            "x": -3,
            "y": 0,
            "z": -1,
            "elements": "immersiveengineering:metal_decoration1@1"
        },
        {
            "x": -4,
            "y": 0,
            "z": -1,
            "elements": "immersiveengineering:metal_decoration1@1"
        },
        {
            "x": -5,
            "y": 0,
            "z": -1,
            "elements": "immersiveengineering:metal_decoration1@1"
        },
        {
            "x": -6,
            "y": 0,
            "z": -1,
            "elements": "modularmachinery:blockcasing@0"
        },
        {
            "x": -7,
            "y": 0,
            "z": -1,
            "elements": "modularmachinery:blockcasing@0"
        },
        {
            "x": -8,
            "y": 0,
            "z": -1,
            "elements": "modularmachinery:blockcasing@0"
        },
        {
            "x": -9,
            "y": 0,
            "z": -1,
            "elements": "immersiveengineering:metal_decoration1@1"
        },
        {
            "x": -7,
            "y": 0,
            "z": -2,
            "elements": "immersiveengineering:sheetmetal@8"
        },
        {
            "x": 3,
            "y": 1,
            "z": 3,
            "elements": "immersiveengineering:metal_decoration1@1"
        },
        {
            "x": -3,
            "y": 1,
            "z": 3,
            "elements": "immersiveengineering:metal_decoration1@1"
        },
        {
            "x": -6,
            "y": 1,
            "z": 3,
            "elements": "modularmachinery:blockcasing@0"
        },
        {
            "x": -7,
            "y": 1,
            "z": 3,
            "elements": "modularmachinery:blockcasing@0"
        },
        {
            "x": -8,
            "y": 1,
            "z": 3,
            "elements": "modularmachinery:blockcasing@0"
        },
        {
            "x": -9,
            "y": 1,
            "z": 3,
            "elements": "immersiveengineering:metal_decoration1@1"
        },
        {
            "x": 2,
            "y": 1,
            "z": 2,
            "elements": "modularmachinery:blockcasing@0"
        },
        {
            "x": 1,
            "y": 1,
            "z": 2,
            "elements": "libvulpes:coil0@4"
        },
        {
            "x": 0,
            "y": 1,
            "z": 2,
            "elements": "modularmachinery:blockcasing@0"
        },
        {
            "x": -1,
            "y": 1,
            "z": 2,
            "elements": "libvulpes:coil0@4"
        },
        {
            "x": -2,
            "y": 1,
            "z": 2,
            "elements": "modularmachinery:blockcasing@0"
        },
        {
            "x": -6,
            "y": 1,
            "z": 2,
            "elements": "modularmachinery:blockcasing@0"
        },
        {
            "x": -8,
            "y": 1,
            "z": 2,
            "elements": "modularmachinery:blockcasing@0"
        },
        {
            "x": 2,
            "y": 1,
            "z": 1,
            "elements": "modularmachinery:blockcasing@0"
        },
        {
            "x": 1,
            "y": 1,
            "z": 1,
            "elements": "libvulpes:coil0@4"
        },
        {
            "x": 0,
            "y": 1,
            "z": 1,
            "elements": "modularmachinery:blockcasing@0"
        },
        {
            "x": -1,
            "y": 1,
            "z": 1,
            "elements": "libvulpes:coil0@4"
        },
        {
            "x": -2,
            "y": 1,
            "z": 1,
            "elements": "modularmachinery:blockcasing@0"
        },
        {
            "x": -6,
            "y": 1,
            "z": 1,
            "elements": "modularmachinery:blockcasing@0"
        },
        {
            "x": -7,
            "y": 1,
            "z": 1,
            "elements": "nuclearcraft:turbine_rotor_blade_steel"
        },
        {
            "x": -8,
            "y": 1,
            "z": 1,
            "elements": "modularmachinery:blockcasing@0"
        },
        {
            "x": 2,
            "y": 1,
            "z": 0,
            "elements": "modularmachinery:blockcasing@0"
        },
        {
            "x": 1,
            "y": 1,
            "z": 0,
            "elements": "libvulpes:coil0@4"
        },
        {
            "x": 0,
            "y": 1,
            "z": 0,
            "elements": "modularmachinery:blockcasing@0"
        },
        {
            "x": -1,
            "y": 1,
            "z": 0,
            "elements": "libvulpes:coil0@4"
        },
        {
            "x": -2,
            "y": 1,
            "z": 0,
            "elements": "modularmachinery:blockcasing@0"
        },
        {
            "x": -6,
            "y": 1,
            "z": 0,
            "elements": "modularmachinery:blockcasing@0"
        },
        {
            "x": -8,
            "y": 1,
            "z": 0,
            "elements": "modularmachinery:blockcasing@0"
        },
        {
            "x": 3,
            "y": 1,
            "z": -1,
            "elements": "immersiveengineering:metal_decoration1@1"
        },
        {
            "x": -3,
            "y": 1,
            "z": -1,
            "elements": "immersiveengineering:metal_decoration1@1"
        },
        {
            "x": -6,
            "y": 1,
            "z": -1,
            "elements": "modularmachinery:blockcasing@0"
        },
        {
            "x": -7,
            "y": 1,
            "z": -1,
            "elements": "modularmachinery:blockcasing@0"
        },
        {
            "x": -8,
            "y": 1,
            "z": -1,
            "elements": "modularmachinery:blockcasing@0"
        },
        {
            "x": -9,
            "y": 1,
            "z": -1,
            "elements": "immersiveengineering:metal_decoration1@1"
        },
        {
            "x": -7,
            "y": 1,
            "z": -2,
            "elements": "immersiveengineering:sheetmetal@8"
        },
        {
            "x": 3,
            "y": 2,
            "z": 2,
            "elements": "immersiveengineering:metal_decoration1@1"
        },
        {
            "x": -3,
            "y": 2,
            "z": 2,
            "elements": "immersiveengineering:metal_decoration1@1"
        },
        {
            "x": -6,
            "y": 2,
            "z": 2,
            "elements": "modularmachinery:blockcasing@0"
        },
        {
            "x": -7,
            "y": 2,
            "z": 2,
            "elements": "modularmachinery:blockcasing@0"
        },
        {
            "x": -8,
            "y": 2,
            "z": 2,
            "elements": "modularmachinery:blockcasing@0"
        },
        {
            "x": -9,
            "y": 2,
            "z": 2,
            "elements": "immersiveengineering:metal_decoration1@1"
        },
        {
            "x": 3,
            "y": 2,
            "z": 1,
            "elements": "immersiveengineering:metal_decoration1@1"
        },
        {
            "x": 2,
            "y": 2,
            "z": 1,
            "elements": "immersiveengineering:metal_decoration1@1"
        },
        {
            "x": 1,
            "y": 2,
            "z": 1,
            "elements": "immersiveengineering:metal_decoration1@1"
        },
        {
            "x": 0,
            "y": 2,
            "z": 1,
            "elements": "immersiveengineering:metal_decoration1@1"
        },
        {
            "x": -1,
            "y": 2,
            "z": 1,
            "elements": "immersiveengineering:metal_decoration1@1"
        },
        {
            "x": -2,
            "y": 2,
            "z": 1,
            "elements": "immersiveengineering:metal_decoration1@1"
        },
        {
            "x": -3,
            "y": 2,
            "z": 1,
            "elements": "immersiveengineering:metal_decoration1@1"
        },
        {
            "x": -4,
            "y": 2,
            "z": 1,
            "elements": "immersiveengineering:metal_decoration1@1"
        },
        {
            "x": -5,
            "y": 2,
            "z": 1,
            "elements": "immersiveengineering:metal_decoration1@1"
        },
        {
            "x": -6,
            "y": 2,
            "z": 1,
            "elements": "modularmachinery:blockcasing@0"
        },
        {
            "x": -7,
            "y": 2,
            "z": 1,
            "elements": "modularmachinery:blockcasing@0"
        },
        {
            "x": -8,
            "y": 2,
            "z": 1,
            "elements": "modularmachinery:blockcasing@0"
        },
        {
            "x": -9,
            "y": 2,
            "z": 1,
            "elements": "immersiveengineering:metal_decoration1@1"
        },
        {
            "x": 3,
            "y": 2,
            "z": 0,
            "elements": "immersiveengineering:metal_decoration1@1"
        },
        {
            "x": -3,
            "y": 2,
            "z": 0,
            "elements": "immersiveengineering:metal_decoration1@1"
        },
        {
            "x": -6,
            "y": 2,
            "z": 0,
            "elements": "modularmachinery:blockcasing@0"
        },
        {
            "x": -7,
            "y": 2,
            "z": 0,
            "elements": "modularmachinery:blockcasing@0"
        },
        {
            "x": -8,
            "y": 2,
            "z": 0,
            "elements": "modularmachinery:blockcasing@0"
        },
        {
            "x": -9,
            "y": 2,
            "z": 0,
            "elements": "immersiveengineering:metal_decoration1@1"
        },
        {
            "x": -7,
            "y": 2,
            "z": -1,
            "elements": "immersiveengineering:sheetmetal@8"
        },
        {
            "x": -7,
            "y": 2,
            "z": -2,
            "elements": "immersiveengineering:sheetmetal@8"
        },
        {
            "x": -7,
            "y": 3,
            "z": 1,
            "elements": "immersiveengineering:sheetmetal@8"
        },
        {
            "x": -7,
            "y": 3,
            "z": 0,
            "elements": "immersiveengineering:sheetmetal@8"
        },
        {
            "x": -7,
            "y": 3,
            "z": -1,
            "elements": "immersiveengineering:sheetmetal@8"
        },
		{
            "x": -9,
            "y": 0,
            "z": 1,
            "elements": "modularmachinery:blockfluidoutputhatch"
        }
    ]
}