{
    "registryname": "cosmic_ray_accumulator",
    "localizedname": "Cosmic Ray Accumulator",
    "modifiers": [],
    "parts": [
		{
			"x": 1,
			"y": 0,
			"z": 0,
			"elements": "modularmachinery:blockcasing@0"
		},
		{
			"x": -1,
			"y": 0,
			"z": 0,
			"elements": "modularmachinery:blockcasing@0"
		},
		{
			"x": 2,
			"y": 0,
			"z": 1,
			"elements": "modularmachinery:blockcasing@0"
		},
		{
			"x": 1,
			"y": 0,
			"z": 1,
			"elements": "modularmachinery:blockcasing@0"
		},
		{
			"x": 0,
			"y": 0,
			"z": 1,
			"elements": "modularmachinery:blockcasing@0"
		},
		{
			"x": -1,
			"y": 0,
			"z": 1,
			"elements": "modularmachinery:blockcasing@0"
		},
		{
			"x": -2,
			"y": 0,
			"z": 1,
			"elements": "modularmachinery:blockcasing@0"
		},
		{
			"x": 2,
			"y": 0,
			"z": 2,
			"elements": "modularmachinery:blockoutputbus"
		},
		{
			"x": 1,
			"y": 0,
			"z": 2,
			"elements": "modularmachinery:blockcasing@0"
		},
		{
			"x": 0,
			"y": 0,
			"z": 2,
			"elements": "modulardiversity:blockbiomedetector"
		},
		{
			"x": -1,
			"y": 0,
			"z": 2,
			"elements": "modularmachinery:blockcasing@0"
		},
		{
			"x": -2,
			"y": 0,
			"z": 2,
			"elements": "modularmachinery:blockinputbus"
		},
		{
			"x": 2,
			"y": 0,
			"z": 3,
			"elements": "modularmachinery:blockcasing@0"
		},
		{
			"x": 1,
			"y": 0,
			"z": 3,
			"elements": "modularmachinery:blockcasing@0"
		},
		{
			"x": 0,
			"y": 0,
			"z": 3,
			"elements": "modularmachinery:blockcasing@0"
		},
		{
			"x": -1,
			"y": 0,
			"z": 3,
			"elements": "modularmachinery:blockcasing@0"
		},
		{
			"x": -2,
			"y": 0,
			"z": 3,
			"elements": "modularmachinery:blockcasing@0"
		},
		{
			"x": 1,
			"y": 0,
			"z": 4,
			"elements": "modularmachinery:blockcasing@0"
		},
		{
			"x": 0,
			"y": 0,
			"z": 4,
			"elements": "modularmachinery:blockenergyinputhatch"
		},
		{
			"x": -1,
			"y": 0,
			"z": 4,
			"elements": "modularmachinery:blockcasing@0"
		},
		{
			"x": 1,
			"y": 1,
			"z": 1,
			"elements": "modularmachinery:blockcasing@5"
		},
		{
			"x": 0,
			"y": 1,
			"z": 1,
			"elements": "modularmachinery:blockcasing@0"
		},
		{
			"x": -1,
			"y": 1,
			"z": 1,
			"elements": "modularmachinery:blockcasing@5"
		},
		{
			"x": 1,
			"y": 1,
			"z": 3,
			"elements": "modularmachinery:blockcasing@5"
		},
		{
			"x": 0,
			"y": 1,
			"z": 3,
			"elements": "modularmachinery:blockcasing@0"
		},
		{
			"x": -1,
			"y": 1,
			"z": 3,
			"elements": "modularmachinery:blockcasing@5"
		},
		{
			"x": 1,
			"y": 1,
			"z": 2,
			"elements": "thebetweenlands:green_middle_gem_block"
		},
		{
			"x": 0,
			"y": 1,
			"z": 2,
			"elements": "advancedrocketry:warpcore"
		},
		{
			"x": -1,
			"y": 1,
			"z": 2,
			"elements": "thebetweenlands:green_middle_gem_block"
		},
		{
			"x": 1,
			"y": 2,
			"z": 2,
			"elements": "thebetweenlands:polished_dentrothyst@0"
		},
		{
			"x": 0,
			"y": 2,
			"z": 2,
			"elements": "appliedenergistics2:quartz_vibrant_glass"
		},
		{
			"x": -1,
			"y": 2,
			"z": 2,
			"elements": "thebetweenlands:polished_dentrothyst@0"
		},
		{
			"x": 1,
			"y": 3,
			"z": 2,
			"elements": "thebetweenlands:polished_dentrothyst@0"
		},
		{
			"x": 0,
			"y": 3,
			"z": 2,
			"elements": "appliedenergistics2:quartz_vibrant_glass"
		},
		{
			"x": -1,
			"y": 3,
			"z": 2,
			"elements": "thebetweenlands:polished_dentrothyst@0"
		},
		{
			"x": 1,
			"y": 4,
			"z": 2,
			"elements": "thebetweenlands:polished_dentrothyst@0"
		},
		{
			"x": 0,
			"y": 4,
			"z": 2,
			"elements": "appliedenergistics2:quartz_vibrant_glass"
		},
		{
			"x": -1,
			"y": 4,
			"z": 2,
			"elements": "thebetweenlands:polished_dentrothyst@0"
		},
		{
			"x": 1,
			"y": 5,
			"z": 2,
			"elements": "thebetweenlands:polished_dentrothyst@0"
		},
		{
			"x": 0,
			"y": 5,
			"z": 2,
			"elements": "appliedenergistics2:quartz_vibrant_glass"
		},
		{
			"x": -1,
			"y": 5,
			"z": 2,
			"elements": "thebetweenlands:polished_dentrothyst@0"
		},
		{
			"x": 1,
			"y": 6,
			"z": 2,
			"elements": "thebetweenlands:polished_dentrothyst@0"
		},
		{
			"x": 0,
			"y": 6,
			"z": 2,
			"elements": "appliedenergistics2:quartz_vibrant_glass"
		},
		{
			"x": -1,
			"y": 6,
			"z": 2,
			"elements": "thebetweenlands:polished_dentrothyst@0"
		},
		{
			"x": 1,
			"y": 7,
			"z": 2,
			"elements": "thebetweenlands:polished_dentrothyst@0"
		},
		{
			"x": 0,
			"y": 7,
			"z": 2,
			"elements": "appliedenergistics2:quartz_vibrant_glass"
		},
		{
			"x": -1,
			"y": 7,
			"z": 2,
			"elements": "thebetweenlands:polished_dentrothyst@0"
		},
		{
			"x": 1,
			"y": 8,
			"z": 2,
			"elements": "thebetweenlands:polished_dentrothyst@0"
		},
		{
			"x": 0,
			"y": 8,
			"z": 2,
			"elements": "appliedenergistics2:quartz_vibrant_glass"
		},
		{
			"x": -1,
			"y": 8,
			"z": 2,
			"elements": "thebetweenlands:polished_dentrothyst@0"
		},
		{
			"x": 1,
			"y": 9,
			"z": 2,
			"elements": "thebetweenlands:polished_dentrothyst@0"
		},
		{
			"x": 0,
			"y": 9,
			"z": 2,
			"elements": "thebetweenlands:polished_dentrothyst@0"
		},
		{
			"x": -1,
			"y": 9,
			"z": 2,
			"elements": "thebetweenlands:polished_dentrothyst@0"
		},
		{
			"x": 2,
			"y": 1,
			"z": 1,
			"elements": "netherex:quartz_fence"
		},
		{
			"x": 2,
			"y": 2,
			"z": 1,
			"elements": "netherex:quartz_fence"
		},
		{
			"x": 2,
			"y": 3,
			"z": 1,
			"elements": "netherex:quartz_fence"
		},
		{
			"x": -2,
			"y": 1,
			"z": 1,
			"elements": "netherex:quartz_fence"
		},
		{
			"x": -2,
			"y": 2,
			"z": 1,
			"elements": "netherex:quartz_fence"
		},
		{
			"x": -2,
			"y": 3,
			"z": 1,
			"elements": "netherex:quartz_fence"
		},
		{
			"x": 2,
			"y": 1,
			"z": 3,
			"elements": "netherex:quartz_fence"
		},
		{
			"x": 2,
			"y": 2,
			"z": 3,
			"elements": "netherex:quartz_fence"
		},
		{
			"x": 2,
			"y": 3,
			"z": 3,
			"elements": "netherex:quartz_fence"
		},
		{
			"x": -2,
			"y": 1,
			"z": 3,
			"elements": "netherex:quartz_fence"
		},
		{
			"x": -2,
			"y": 2,
			"z": 3,
			"elements": "netherex:quartz_fence"
		},
		{
			"x": -2,
			"y": 3,
			"z": 3,
			"elements": "netherex:quartz_fence"
		}
    ]
}